reported_result/report-9/ART_TFC/output/output6.txt

Iceberg	1	2	2	10	6	BUY 	1	---	0
NewOrderRs	Rejected
	Trades	0
	Orders	0
	Credits	7
	Credit	1	17
	Credit	2	7
	Credit	3	12
	Credit	4	5
	Credit	5	14
	Credit	6	16
	Credit	7	11
	Ownerships	7
	Ownership	1	38
	Ownership	2	91
	Ownership	3	81
	Ownership	4	75
	Ownership	5	76
	Ownership	6	35
	Ownership	7	95
	ReferencePrice	5
	StaticPriceBandLowerLimit	0.6
	StaticPriceBandUpperLimit	0.8
	TotalShares	100
	OwnershipUpperLimit	0.2
	TickSize	1
	LotSize	1
Limit	2	5	2	7	3	SELL	0	---	0
NewOrderRs	Accepted
	Trades	0
	Orders	1
	Order	Limit	2	5	2	7	3	SELL	0	---	0
	Credits	7
	Credit	1	17
	Credit	2	7
	Credit	3	12
	Credit	4	5
	Credit	5	14
	Credit	6	16
	Credit	7	11
	Ownerships	7
	Ownership	1	38
	Ownership	2	91
	Ownership	3	81
	Ownership	4	75
	Ownership	5	76
	Ownership	6	35
	Ownership	7	95
	ReferencePrice	5
	StaticPriceBandLowerLimit	0.6
	StaticPriceBandUpperLimit	0.8
	TotalShares	100
	OwnershipUpperLimit	0.2
	TickSize	1
	LotSize	1
Limit	3	7	2	3	2	SELL	0	---	0
NewOrderRs	Accepted
	Trades	0
	Orders	2
	Order	Limit	3	7	2	3	2	SELL	0	---	0
	Order	Limit	2	5	2	7	3	SELL	0	---	0
	Credits	7
	Credit	1	17
	Credit	2	7
	Credit	3	12
	Credit	4	5
	Credit	5	14
	Credit	6	16
	Credit	7	11
	Ownerships	7
	Ownership	1	38
	Ownership	2	91
	Ownership	3	81
	Ownership	4	75
	Ownership	5	76
	Ownership	6	35
	Ownership	7	95
	ReferencePrice	5
	StaticPriceBandLowerLimit	0.6
	StaticPriceBandUpperLimit	0.8
	TotalShares	100
	OwnershipUpperLimit	0.2
	TickSize	1
	LotSize	1
Iceberg	4	3	3	9	2	BUY 	1	---	0
NewOrderRs	Rejected
	Trades	0
	Orders	2
	Order	Limit	3	7	2	3	2	SELL	0	---	0
	Order	Limit	2	5	2	7	3	SELL	0	---	0
	Credits	7
	Credit	1	17
	Credit	2	7
	Credit	3	12
	Credit	4	5
	Credit	5	14
	Credit	6	16
	Credit	7	11
	Ownerships	7
	Ownership	1	38
	Ownership	2	91
	Ownership	3	81
	Ownership	4	75
	Ownership	5	76
	Ownership	6	35
	Ownership	7	95
	ReferencePrice	5
	StaticPriceBandLowerLimit	0.6
	StaticPriceBandUpperLimit	0.8
	TotalShares	100
	OwnershipUpperLimit	0.2
	TickSize	1
	LotSize	1
CancelOrderRs	Rejected
	Orders	2
	Order	Limit	3	7	2	3	2	SELL	0	---	0
	Order	Limit	2	5	2	7	3	SELL	0	---	0
	Credits	7
	Credit	1	17
	Credit	2	7
	Credit	3	12
	Credit	4	5
	Credit	5	14
	Credit	6	16
	Credit	7	11
	Ownerships	7
	Ownership	1	38
	Ownership	2	91
	Ownership	3	81
	Ownership	4	75
	Ownership	5	76
	Ownership	6	35
	Ownership	7	95
	ReferencePrice	5
	StaticPriceBandLowerLimit	0.6
	StaticPriceBandUpperLimit	0.8
	TotalShares	100
	OwnershipUpperLimit	0.2
	TickSize	1
	LotSize	1
Iceberg	6	4	4	7	2	BUY 	2	---	0
NewOrderRs	Rejected
	Trades	0
	Orders	2
	Order	Limit	3	7	2	3	2	SELL	0	---	0
	Order	Limit	2	5	2	7	3	SELL	0	---	0
	Credits	7
	Credit	1	17
	Credit	2	7
	Credit	3	12
	Credit	4	5
	Credit	5	14
	Credit	6	16
	Credit	7	11
	Ownerships	7
	Ownership	1	38
	Ownership	2	91
	Ownership	3	81
	Ownership	4	75
	Ownership	5	76
	Ownership	6	35
	Ownership	7	95
	ReferencePrice	5
	StaticPriceBandLowerLimit	0.6
	StaticPriceBandUpperLimit	0.8
	TotalShares	100
	OwnershipUpperLimit	0.2
	TickSize	1
	LotSize	1
Limit	7	3	6	4	8	SELL	0	FAK	0
NewOrderRs	Eliminated
	Trades	0
	Orders	2
	Order	Limit	3	7	2	3	2	SELL	0	---	0
	Order	Limit	2	5	2	7	3	SELL	0	---	0
	Credits	7
	Credit	1	17
	Credit	2	7
	Credit	3	12
	Credit	4	5
	Credit	5	14
	Credit	6	16
	Credit	7	11
	Ownerships	7
	Ownership	1	38
	Ownership	2	91
	Ownership	3	81
	Ownership	4	75
	Ownership	5	76
	Ownership	6	35
	Ownership	7	95
	ReferencePrice	5
	StaticPriceBandLowerLimit	0.6
	StaticPriceBandUpperLimit	0.8
	TotalShares	100
	OwnershipUpperLimit	0.2
	TickSize	1
	LotSize	1
Iceberg	8	2	5	7	6	BUY 	1	---	0
NewOrderRs	Rejected
	Trades	0
	Orders	2
	Order	Limit	3	7	2	3	2	SELL	0	---	0
	Order	Limit	2	5	2	7	3	SELL	0	---	0
	Credits	7
	Credit	1	17
	Credit	2	7
	Credit	3	12
	Credit	4	5
	Credit	5	14
	Credit	6	16
	Credit	7	11
	Ownerships	7
	Ownership	1	38
	Ownership	2	91
	Ownership	3	81
	Ownership	4	75
	Ownership	5	76
	Ownership	6	35
	Ownership	7	95
	ReferencePrice	5
	StaticPriceBandLowerLimit	0.6
	StaticPriceBandUpperLimit	0.8
	TotalShares	100
	OwnershipUpperLimit	0.2
	TickSize	1
	LotSize	1
Limit	9	7	1	2	3	BUY 	1	---	0
NewOrderRs	Rejected
	Trades	0
	Orders	2
	Order	Limit	3	7	2	3	2	SELL	0	---	0
	Order	Limit	2	5	2	7	3	SELL	0	---	0
	Credits	7
	Credit	1	17
	Credit	2	7
	Credit	3	12
	Credit	4	5
	Credit	5	14
	Credit	6	16
	Credit	7	11
	Ownerships	7
	Ownership	1	38
	Ownership	2	91
	Ownership	3	81
	Ownership	4	75
	Ownership	5	76
	Ownership	6	35
	Ownership	7	95
	ReferencePrice	5
	StaticPriceBandLowerLimit	0.6
	StaticPriceBandUpperLimit	0.8
	TotalShares	100
	OwnershipUpperLimit	0.2
	TickSize	1
	LotSize	1
Iceberg	10	7	1	7	2	BUY 	1	---	0
ReplaceOrderRs	Rejected
	Trades	0
	Orders	2
	Order	Limit	3	7	2	3	2	SELL	0	---	0
	Order	Limit	2	5	2	7	3	SELL	0	---	0
	Credits	7
	Credit	1	17
	Credit	2	7
	Credit	3	12
	Credit	4	5
	Credit	5	14
	Credit	6	16
	Credit	7	11
	Ownerships	7
	Ownership	1	38
	Ownership	2	91
	Ownership	3	81
	Ownership	4	75
	Ownership	5	76
	Ownership	6	35
	Ownership	7	95
	ReferencePrice	5
	StaticPriceBandLowerLimit	0.6
	StaticPriceBandUpperLimit	0.8
	TotalShares	100
	OwnershipUpperLimit	0.2
	TickSize	1
	LotSize	1
Iceberg	11	1	2	4	8	BUY 	0	---	0
NewOrderRs	Rejected
	Trades	0
	Orders	2
	Order	Limit	3	7	2	3	2	SELL	0	---	0
	Order	Limit	2	5	2	7	3	SELL	0	---	0
	Credits	7
	Credit	1	17
	Credit	2	7
	Credit	3	12
	Credit	4	5
	Credit	5	14
	Credit	6	16
	Credit	7	11
	Ownerships	7
	Ownership	1	38
	Ownership	2	91
	Ownership	3	81
	Ownership	4	75
	Ownership	5	76
	Ownership	6	35
	Ownership	7	95
	ReferencePrice	5
	StaticPriceBandLowerLimit	0.6
	StaticPriceBandUpperLimit	0.8
	TotalShares	100
	OwnershipUpperLimit	0.2
	TickSize	1
	LotSize	1
Limit	12	6	3	4	4	SELL	4	---	0
NewOrderRs	Eliminated
	Trades	0
	Orders	2
	Order	Limit	3	7	2	3	2	SELL	0	---	0
	Order	Limit	2	5	2	7	3	SELL	0	---	0
	Credits	7
	Credit	1	17
	Credit	2	7
	Credit	3	12
	Credit	4	5
	Credit	5	14
	Credit	6	16
	Credit	7	11
	Ownerships	7
	Ownership	1	38
	Ownership	2	91
	Ownership	3	81
	Ownership	4	75
	Ownership	5	76
	Ownership	6	35
	Ownership	7	95
	ReferencePrice	5
	StaticPriceBandLowerLimit	0.6
	StaticPriceBandUpperLimit	0.8
	TotalShares	100
	OwnershipUpperLimit	0.2
	TickSize	1
	LotSize	1
Limit	13	4	5	4	6	SELL	0	---	0
NewOrderRs	Accepted
	Trades	0
	Orders	3
	Order	Limit	3	7	2	3	2	SELL	0	---	0
	Order	Limit	13	4	5	4	6	SELL	0	---	0
	Order	Limit	2	5	2	7	3	SELL	0	---	0
	Credits	7
	Credit	1	17
	Credit	2	7
	Credit	3	12
	Credit	4	5
	Credit	5	14
	Credit	6	16
	Credit	7	11
	Ownerships	7
	Ownership	1	38
	Ownership	2	91
	Ownership	3	81
	Ownership	4	75
	Ownership	5	76
	Ownership	6	35
	Ownership	7	95
	ReferencePrice	5
	StaticPriceBandLowerLimit	0.6
	StaticPriceBandUpperLimit	0.8
	TotalShares	100
	OwnershipUpperLimit	0.2
	TickSize	1
	LotSize	1
Iceberg	14	1	4	5	1	SELL	0	---	0
NewOrderRs	Accepted
	Trades	0
	Orders	4
	Order	Limit	3	7	2	3	2	SELL	0	---	0
	Order	Limit	13	4	5	4	6	SELL	0	---	0
	Order	Iceberg	14	1	4	5	1	SELL	0	---	1
	Order	Limit	2	5	2	7	3	SELL	0	---	0
	Credits	7
	Credit	1	17
	Credit	2	7
	Credit	3	12
	Credit	4	5
	Credit	5	14
	Credit	6	16
	Credit	7	11
	Ownerships	7
	Ownership	1	38
	Ownership	2	91
	Ownership	3	81
	Ownership	4	75
	Ownership	5	76
	Ownership	6	35
	Ownership	7	95
	ReferencePrice	5
	StaticPriceBandLowerLimit	0.6
	StaticPriceBandUpperLimit	0.8
	TotalShares	100
	OwnershipUpperLimit	0.2
	TickSize	1
	LotSize	1
CancelOrderRs	Accepted
	Orders	3
	Order	Limit	3	7	2	3	2	SELL	0	---	0
	Order	Limit	13	4	5	4	6	SELL	0	---	0
	Order	Limit	2	5	2	7	3	SELL	0	---	0
	Credits	7
	Credit	1	17
	Credit	2	7
	Credit	3	12
	Credit	4	5
	Credit	5	14
	Credit	6	16
	Credit	7	11
	Ownerships	7
	Ownership	1	38
	Ownership	2	91
	Ownership	3	81
	Ownership	4	75
	Ownership	5	76
	Ownership	6	35
	Ownership	7	95
	ReferencePrice	5
	StaticPriceBandLowerLimit	0.6
	StaticPriceBandUpperLimit	0.8
	TotalShares	100
	OwnershipUpperLimit	0.2
	TickSize	1
	LotSize	1
Iceberg	16	6	6	5	5	BUY 	0	---	0
NewOrderRs	Rejected
	Trades	0
	Orders	3
	Order	Limit	3	7	2	3	2	SELL	0	---	0
	Order	Limit	13	4	5	4	6	SELL	0	---	0
	Order	Limit	2	5	2	7	3	SELL	0	---	0
	Credits	7
	Credit	1	17
	Credit	2	7
	Credit	3	12
	Credit	4	5
	Credit	5	14
	Credit	6	16
	Credit	7	11
	Ownerships	7
	Ownership	1	38
	Ownership	2	91
