reported_result/report-9/ART_TFC/output/output7.txt

Iceberg	1	5	7	2	8	SELL	0	---	0
NewOrderRs	Accepted
	Trades	0
	Orders	1
	Order	Iceberg	1	5	7	2	8	SELL	0	---	2
	Credits	7
	Credit	1	4
	Credit	2	17
	Credit	3	7
	Credit	4	6
	Credit	5	13
	Credit	6	13
	Credit	7	16
	Ownerships	7
	Ownership	1	23
	Ownership	2	35
	Ownership	3	69
	Ownership	4	79
	Ownership	5	83
	Ownership	6	22
	Ownership	7	50
	ReferencePrice	5
	StaticPriceBandLowerLimit	0.6
	StaticPriceBandUpperLimit	0.8
	TotalShares	100
	OwnershipUpperLimit	0.2
	TickSize	1
	LotSize	1
Iceberg	2	7	3	3	4	SELL	0	---	0
NewOrderRs	Accepted
	Trades	0
	Orders	2
	Order	Iceberg	1	5	7	2	8	SELL	0	---	2
	Order	Iceberg	2	7	3	3	4	SELL	0	---	2
	Credits	7
	Credit	1	4
	Credit	2	17
	Credit	3	7
	Credit	4	6
	Credit	5	13
	Credit	6	13
	Credit	7	16
	Ownerships	7
	Ownership	1	23
	Ownership	2	35
	Ownership	3	69
	Ownership	4	79
	Ownership	5	83
	Ownership	6	22
	Ownership	7	50
	ReferencePrice	5
	StaticPriceBandLowerLimit	0.6
	StaticPriceBandUpperLimit	0.8
	TotalShares	100
	OwnershipUpperLimit	0.2
	TickSize	1
	LotSize	1
Limit	3	7	4	9	3	BUY 	0	FAK	0
NewOrderRs	Rejected
	Trades	0
	Orders	2
	Order	Iceberg	1	5	7	2	8	SELL	0	---	2
	Order	Iceberg	2	7	3	3	4	SELL	0	---	2
	Credits	7
	Credit	1	4
	Credit	2	17
	Credit	3	7
	Credit	4	6
	Credit	5	13
	Credit	6	13
	Credit	7	16
	Ownerships	7
	Ownership	1	23
	Ownership	2	35
	Ownership	3	69
	Ownership	4	79
	Ownership	5	83
	Ownership	6	22
	Ownership	7	50
	ReferencePrice	5
	StaticPriceBandLowerLimit	0.6
	StaticPriceBandUpperLimit	0.8
	TotalShares	100
	OwnershipUpperLimit	0.2
	TickSize	1
	LotSize	1
Limit	4	3	1	1	6	BUY 	0	---	0
NewOrderRs	Rejected
	Trades	0
	Orders	2
	Order	Iceberg	1	5	7	2	8	SELL	0	---	2
	Order	Iceberg	2	7	3	3	4	SELL	0	---	2
	Credits	7
	Credit	1	4
	Credit	2	17
	Credit	3	7
	Credit	4	6
	Credit	5	13
	Credit	6	13
	Credit	7	16
	Ownerships	7
	Ownership	1	23
	Ownership	2	35
	Ownership	3	69
	Ownership	4	79
	Ownership	5	83
	Ownership	6	22
	Ownership	7	50
	ReferencePrice	5
	StaticPriceBandLowerLimit	0.6
	StaticPriceBandUpperLimit	0.8
	TotalShares	100
	OwnershipUpperLimit	0.2
	TickSize	1
	LotSize	1
CancelOrderRs	Rejected
	Orders	2
	Order	Iceberg	1	5	7	2	8	SELL	0	---	2
	Order	Iceberg	2	7	3	3	4	SELL	0	---	2
	Credits	7
	Credit	1	4
	Credit	2	17
	Credit	3	7
	Credit	4	6
	Credit	5	13
	Credit	6	13
	Credit	7	16
	Ownerships	7
	Ownership	1	23
	Ownership	2	35
	Ownership	3	69
	Ownership	4	79
	Ownership	5	83
	Ownership	6	22
	Ownership	7	50
	ReferencePrice	5
	StaticPriceBandLowerLimit	0.6
	StaticPriceBandUpperLimit	0.8
	TotalShares	100
	OwnershipUpperLimit	0.2
	TickSize	1
	LotSize	1
Limit	6	4	2	3	1	BUY 	1	---	0
NewOrderRs	Rejected
	Trades	0
	Orders	2
	Order	Iceberg	1	5	7	2	8	SELL	0	---	2
	Order	Iceberg	2	7	3	3	4	SELL	0	---	2
	Credits	7
	Credit	1	4
	Credit	2	17
	Credit	3	7
	Credit	4	6
	Credit	5	13
	Credit	6	13
	Credit	7	16
	Ownerships	7
	Ownership	1	23
	Ownership	2	35
	Ownership	3	69
	Ownership	4	79
	Ownership	5	83
	Ownership	6	22
	Ownership	7	50
	ReferencePrice	5
	StaticPriceBandLowerLimit	0.6
	StaticPriceBandUpperLimit	0.8
	TotalShares	100
	OwnershipUpperLimit	0.2
	TickSize	1
	LotSize	1
Limit	7	4	1	6	2	SELL	0	FAK	0
NewOrderRs	Eliminated
	Trades	0
	Orders	2
	Order	Iceberg	1	5	7	2	8	SELL	0	---	2
	Order	Iceberg	2	7	3	3	4	SELL	0	---	2
	Credits	7
	Credit	1	4
	Credit	2	17
	Credit	3	7
	Credit	4	6
	Credit	5	13
	Credit	6	13
	Credit	7	16
	Ownerships	7
	Ownership	1	23
	Ownership	2	35
	Ownership	3	69
	Ownership	4	79
	Ownership	5	83
	Ownership	6	22
	Ownership	7	50
	ReferencePrice	5
	StaticPriceBandLowerLimit	0.6
	StaticPriceBandUpperLimit	0.8
	TotalShares	100
	OwnershipUpperLimit	0.2
	TickSize	1
	LotSize	1
Iceberg	8	5	7	3	1	SELL	1	---	0
NewOrderRs	Eliminated
	Trades	0
	Orders	2
	Order	Iceberg	1	5	7	2	8	SELL	0	---	2
	Order	Iceberg	2	7	3	3	4	SELL	0	---	2
	Credits	7
	Credit	1	4
	Credit	2	17
	Credit	3	7
	Credit	4	6
	Credit	5	13
	Credit	6	13
	Credit	7	16
	Ownerships	7
	Ownership	1	23
	Ownership	2	35
	Ownership	3	69
	Ownership	4	79
	Ownership	5	83
	Ownership	6	22
	Ownership	7	50
	ReferencePrice	5
	StaticPriceBandLowerLimit	0.6
	StaticPriceBandUpperLimit	0.8
	TotalShares	100
	OwnershipUpperLimit	0.2
	TickSize	1
	LotSize	1
Iceberg	9	2	2	1	8	BUY 	0	---	0
NewOrderRs	Rejected
	Trades	0
	Orders	2
	Order	Iceberg	1	5	7	2	8	SELL	0	---	2
	Order	Iceberg	2	7	3	3	4	SELL	0	---	2
	Credits	7
	Credit	1	4
	Credit	2	17
	Credit	3	7
	Credit	4	6
	Credit	5	13
	Credit	6	13
	Credit	7	16
	Ownerships	7
	Ownership	1	23
	Ownership	2	35
	Ownership	3	69
	Ownership	4	79
	Ownership	5	83
	Ownership	6	22
	Ownership	7	50
	ReferencePrice	5
	StaticPriceBandLowerLimit	0.6
	StaticPriceBandUpperLimit	0.8
	TotalShares	100
	OwnershipUpperLimit	0.2
	TickSize	1
	LotSize	1
Iceberg	10	2	2	3	8	BUY 	1	---	0
ReplaceOrderRs	Rejected
	Trades	0
	Orders	2
	Order	Iceberg	1	5	7	2	8	SELL	0	---	2
	Order	Iceberg	2	7	3	3	4	SELL	0	---	2
	Credits	7
	Credit	1	4
	Credit	2	17
	Credit	3	7
	Credit	4	6
	Credit	5	13
	Credit	6	13
	Credit	7	16
	Ownerships	7
	Ownership	1	23
	Ownership	2	35
	Ownership	3	69
	Ownership	4	79
	Ownership	5	83
	Ownership	6	22
	Ownership	7	50
	ReferencePrice	5
	StaticPriceBandLowerLimit	0.6
	StaticPriceBandUpperLimit	0.8
	TotalShares	100
	OwnershipUpperLimit	0.2
	TickSize	1
	LotSize	1
Limit	11	7	4	9	1	SELL	0	---	0
NewOrderRs	Accepted
	Trades	0
	Orders	3
	Order	Iceberg	1	5	7	2	8	SELL	0	---	2
	Order	Iceberg	2	7	3	3	4	SELL	0	---	2
	Order	Limit	11	7	4	9	1	SELL	0	---	0
	Credits	7
	Credit	1	4
	Credit	2	17
	Credit	3	7
	Credit	4	6
	Credit	5	13
	Credit	6	13
	Credit	7	16
	Ownerships	7
	Ownership	1	23
	Ownership	2	35
	Ownership	3	69
	Ownership	4	79
	Ownership	5	83
	Ownership	6	22
	Ownership	7	50
	ReferencePrice	5
	StaticPriceBandLowerLimit	0.6
	StaticPriceBandUpperLimit	0.8
	TotalShares	100
	OwnershipUpperLimit	0.2
	TickSize	1
	LotSize	1
Iceberg	12	3	3	8	7	SELL	0	---	0
NewOrderRs	Accepted
	Trades	0
	Orders	4
	Order	Iceberg	1	5	7	2	8	SELL	0	---	2
	Order	Iceberg	2	7	3	3	4	SELL	0	---	2
	Order	Iceberg	12	3	3	8	7	SELL	0	---	7
	Order	Limit	11	7	4	9	1	SELL	0	---	0
	Credits	7
	Credit	1	4
	Credit	2	17
	Credit	3	7
	Credit	4	6
	Credit	5	13
	Credit	6	13
	Credit	7	16
	Ownerships	7
	Ownership	1	23
	Ownership	2	35
	Ownership	3	69
	Ownership	4	79
	Ownership	5	83
	Ownership	6	22
	Ownership	7	50
	ReferencePrice	5
	StaticPriceBandLowerLimit	0.6
	StaticPriceBandUpperLimit	0.8
	TotalShares	100
	OwnershipUpperLimit	0.2
	TickSize	1
	LotSize	1
Limit	13	2	5	3	2	BUY 	0	---	0
NewOrderRs	Rejected
	Trades	0
	Orders	4
	Order	Iceberg	1	5	7	2	8	SELL	0	---	2
	Order	Iceberg	2	7	3	3	4	SELL	0	---	2
	Order	Iceberg	12	3	3	8	7	SELL	0	---	7
	Order	Limit	11	7	4	9	1	SELL	0	---	0
	Credits	7
	Credit	1	4
	Credit	2	17
	Credit	3	7
	Credit	4	6
	Credit	5	13
	Credit	6	13
	Credit	7	16
	Ownerships	7
	Ownership	1	23
	Ownership	2	35
	Ownership	3	69
	Ownership	4	79
	Ownership	5	83
	Ownership	6	22
	Ownership	7	50
	ReferencePrice	5
	StaticPriceBandLowerLimit	0.6
	StaticPriceBandUpperLimit	0.8
	TotalShares	100
	OwnershipUpperLimit	0.2
	TickSize	1
	LotSize	1
Iceberg	14	1	3	7	7	BUY 	2	---	0
NewOrderRs	Rejected
	Trades	0
	Orders	4
	Order	Iceberg	1	5	7	2	8	SELL	0	---	2
	Order	Iceberg	2	7	3	3	4	SELL	0	---	2
	Order	Iceberg	12	3	3	8	7	SELL	0	---	7
	Order	Limit	11	7	4	9	1	SELL	0	---	0
	Credits	7
	Credit	1	4
	Credit	2	17
	Credit	3	7
	Credit	4	6
	Credit	5	13
	Credit	6	13
	Credit	7	16
	Ownerships	7
	Ownership	1	23
	Ownership	2	35
	Ownership	3	69
	Ownership	4	79
	Ownership	5	83
	Ownership	6	22
	Ownership	7	50
	ReferencePrice	5
	StaticPriceBandLowerLimit	0.6
	StaticPriceBandUpperLimit	0.8
	TotalShares	100
	OwnershipUpperLimit	0.2
	TickSize	1
	LotSize	1
CancelOrderRs	Rejected
	Orders	4
	Order	Iceberg	1	5	7	2	8	SELL	0	---	2
	Order	Iceberg	2	7	3	3	4	SELL	0	---	2
	Order	Iceberg	12	3	3	8	7	SELL	0	---	7
	Order	Limit	11	7	4	9	1	SELL	0	---	0
	Credits	7
	Credit	1	4
	Credit	2	17
	Credit	3	7
	Credit	4	6
	Credit	5	13
	Credit	6	13
	Credit	7	16
	Ownerships	7
	Ownership	1	23
	Ownership	2	35
	Ownership	3	69
	Ownership	4	79
	Ownership	5	83
	Ownership	6	22
	Ownership	7	50
	ReferencePrice	5
	StaticPriceBandLowerLimit	0.6
	StaticPriceBandUpperLimit	0.8
	TotalShares	100
	OwnershipUpperLimit	0.2
	TickSize	1
	LotSize	1
Limit	16	1	1	10	7	SELL	1	---	0
